Workbook

Sheet 도서목록
B1: =COUNTA($B$15:B2108) -> 559 | C1: BOOKS | E1: =COUNTBLANK($E$15:E2108) -> 1535 | F1: =COUNTBLANK($F$15:F2108) -> 1535 | H1: =COUNTA($H$15:H2108) -> 309 | I1: =COUNTA($H$15:I2108) -> 618
B2: 책 이름 | C2: 작가 | D2: 출판사 | E2: =CONCATENATE("대현","(",E1,")") -> 대현(1535) | F2: =CONCATENATE("문선","(",F1,")") -> 문선(1535) | G2: 구입 날짜 | H2: 상태 | I2: 기부/판매월
E3: =_xludf.IFS(COUNTIF(보류목록!$B$3:$B$1000, B3)>0, "-",COUNTIF(독서목록!$C$2:$C$1091, B3)=0, , COUNTIF(독서목록!$C$2:$C$1091, B3)>0, COUNTIF(독서목록!$C$2:$C$1091, B3)) -> #NAME? | F3: =_xludf.IFS(COUNTIF(보류목록!$C$3:$C$1000, B3)>0, "-",COUNTIF(독서목록!$D$2:$D$1091, B3)=0, , COUNTIF(독서목록!$D$2:$D$1091, B3)>0, COUNTIF(독서목록!$D$2:$D$1091, B3)) -> #NAME?
B4: 내 이름은 빨강1 | C4: 오르한 파묵 | D4: 민음사 | E4: =_xludf.IFS(COUNTIF(보류목록!$B$3:$B$1000, B4)>0, "-",COUNTIF(독서목록!$C$2:$C$1091, B4)=0, , COUNTIF(독서목록!$C$2:$C$1091, B4)>0, COUNTIF(독서목록!$C$2:$C$1091, B4)) -> #NAME? | F4: =_xludf.IFS(COUNTIF(보류목록!$C$3:$C$1000, B4)>0, "-",COUNTIF(독서목록!$D$2:$D$1091, B4)=0, , COUNTIF(독서목록!$D$2:$D$1091, B4)>0, COUNTIF(독서목록!$D$2:$D$1091, B4)) -> #NAME? | G4: 2026.04.03
B5: 내 이름은 빨강2 | C5: 오르한 파묵 | D5: 민음사 | E5: =_xludf.IFS(COUNTIF(보류목록!$B$3:$B$1000, B5)>0, "-",COUNTIF(독서목록!$C$2:$C$1091, B5)=0, , COUNTIF(독서목록!$C$2:$C$1091, B5)>0, COUNTIF(독서목록!$C$2:$C$1091, B5)) -> #NAME? | F5: =_xludf.IFS(COUNTIF(보류목록!$C$3:$C$1000, B5)>0, "-",COUNTIF(독서목록!$D$2:$D$1091, B5)=0, , COUNTIF(독서목록!$D$2:$D$1091, B5)>0, COUNTIF(독서목록!$D$2:$D$1091, B5)) -> #NAME? | G5: 2026.04.03
B6: 빛이 이끄는 곳으로 | C6: 백희성 | D6: 북로망스 | E6: =_xludf.IFS(COUNTIF(보류목록!$B$3:$B$1000, B6)>0, "-",COUNTIF(독서목록!$C$2:$C$1091, B6)=0, , COUNTIF(독서목록!$C$2:$C$1091, B6)>0, COUNTIF(독서목록!$C$2:$C$1091, B6)) -> #NAME? | F6: =_xludf.IFS(COUNTIF(보류목록!$C$3:$C$1000, B6)>0, "-",COUNTIF(독서목록!$D$2:$D$1091, B6)=0, , COUNTIF(독서목록!$D$2:$D$1091, B6)>0, COUNTIF(독서목록!$D$2:$D$1091, B6)) -> #NAME? | G6: 2026.04.03
B7: 킬리만조로의 눈 | C7: 어니스트 헤밍웨이 | D7: 문학동네 | E7: =_xludf.IFS(COUNTIF(보류목록!$B$3:$B$1000, B7)>0, "-",COUNTIF(독서목록!$C$2:$C$1091, B7)=0, , COUNTIF(독서목록!$C$2:$C$1091, B7)>0, COUNTIF(독서목록!$C$2:$C$1091, B7)) -> #NAME? | F7: =_xludf.IFS(COUNTIF(보류목록!$C$3:$C$1000, B7)>0, "-",COUNTIF(독서목록!$D$2:$D$1091, B7)=0, , COUNTIF(독서목록!$D$2:$D$1091, B7)>0, COUNTIF(독서목록!$D$2:$D$1091, B7)) -> #NAME? | G7: 2026.04.03
B8: 모순 | C8: 양귀자 | D8: 쓰다 | E8: =_xludf.IFS(COUNTIF(보류목록!$B$3:$B$1000, B8)>0, "-",COUNTIF(독서목록!$C$2:$C$1091, B8)=0, , COUNTIF(독서목록!$C$2:$C$1091, B8)>0, COUNTIF(독서목록!$C$2:$C$1091, B8)) -> #NAME? | F8: =_xludf.IFS(COUNTIF(보류목록!$C$3:$C$1000, B8)>0, "-",COUNTIF(독서목록!$D$2:$D$1091, B8)=0, , COUNTIF(독서목록!$D$2:$D$1091, B8)>0, COUNTIF(독서목록!$D$2:$D$1091, B8)) -> #NAME? | G8: 2026. 03.03
B9: 쓰는 사람 | C9: 백희성 | D9: 교보문고 | E9: =_xludf.IFS(COUNTIF(보류목록!$B$3:$B$1000, B9)>0, "-",COUNTIF(독서목록!$C$2:$C$1091, B9)=0, , COUNTIF(독서목록!$C$2:$C$1091, B9)>0, COUNTIF(독서목록!$C$2:$C$1091, B9)) -> #NAME? | F9: =_xludf.IFS(COUNTIF(보류목록!$C$3:$C$1000, B9)>0, "-",COUNTIF(독서목록!$D$2:$D$1091, B9)=0, , COUNTIF(독서목록!$D$2:$D$1091, B9)>0, COUNTIF(독서목록!$D$2:$D$1091, B9)) -> #NAME? | G9: 2026. 03.03
B10: 어떻게 지내요 | C10: 시그리드 누네즈 | D10: 엘리 | E10: =_xludf.IFS(COUNTIF(보류목록!$B$3:$B$1000, B10)>0, "-",COUNTIF(독서목록!$C$2:$C$1091, B10)=0, , COUNTIF(독서목록!$C$2:$C$1091, B10)>0, COUNTIF(독서목록!$C$2:$C$1091, B10)) -> #NAME? | F10: =_xludf.IFS(COUNTIF(보류목록!$C$3:$C$1000, B10)>0, "-",COUNTIF(독서목록!$D$2:$D$1091, B10)=0, , COUNTIF(독서목록!$D$2:$D$1091, B10)>0, COUNTIF(독서목록!$D$2:$D$1091, B10)) -> #NAME? | G10: 2026. 03.03
B11: 자기만의 방 | C11: 버지니아 울프 | D11: 열림책들 | E11: =_xludf.IFS(COUNTIF(보류목록!$B$3:$B$1000, B11)>0, "-",COUNTIF(독서목록!$C$2:$C$1091, B11)=0, , COUNTIF(독서목록!$C$2:$C$1091, B11)>0, COUNTIF(독서목록!$C$2:$C$1091, B11)) -> #NAME? | F11: =_xludf.IFS(COUNTIF(보류목록!$C$3:$C$1000, B11)>0, "-",COUNTIF(독서목록!$D$2:$D$1091, B11)=0, , COUNTIF(독서목록!$D$2:$D$1091, B11)>0, COUNTIF(독서목록!$D$2:$D$1091, B11)) -> #NAME? | G11: 2026. 03.03
B12: 괴테는 모든 것을 말했다 | C12: 스즈키 유이 | D12: 리프 | E12: =_xludf.IFS(COUNTIF(보류목록!$B$3:$B$1000, B12)>0, "-",COUNTIF(독서목록!$C$2:$C$1091, B12)=0, , COUNTIF(독서목록!$C$2:$C$1091, B12)>0, COUNTIF(독서목록!$C$2:$C$1091, B12)) -> #NAME? | F12: =_xludf.IFS(COUNTIF(보류목록!$C$3:$C$1000, B12)>0, "-",COUNTIF(독서목록!$D$2:$D$1091, B12)=0, , COUNTIF(독서목록!$D$2:$D$1091, B12)>0, COUNTIF(독서목록!$D$2:$D$1091, B12)) -> #NAME? | G12: 2026.02.02
B13: 안녕이라 그랬어 | C13: 김애란 | D13: 문학동네 | E13: =_xludf.IFS(COUNTIF(보류목록!$B$3:$B$1000, B13)>0, "-",COUNTIF(독서목록!$C$2:$C$1091, B13)=0, , COUNTIF(독서목록!$C$2:$C$1091, B13)>0, COUNTIF(독서목록!$C$2:$C$1091, B13)) -> #NAME? | F13: =_xludf.IFS(COUNTIF(보류목록!$C$3:$C$1000, B13)>0, "-",COUNTIF(독서목록!$D$2:$D$1091, B13)=0, , COUNTIF(독서목록!$D$2:$D$1091, B13)>0, COUNTIF(독서목록!$D$2:$D$1091, B13)) -> #NAME? | G13: 2026.02.02
B14: 편안함의 습 | C14: 마이클 이스터 | D14: 수오서재 | E14: =_xludf.IFS(COUNTIF(보류목록!$B$3:$B$1000, B14)>0, "-",COUNTIF(독서목록!$C$2:$C$1091, B14)=0, , COUNTIF(독서목록!$C$2:$C$1091, B14)>0, COUNTIF(독서목록!$C$2:$C$1091, B14)) -> #NAME? | F14: =_xludf.IFS(COUNTIF(보류목록!$C$3:$C$1000, B14)>0, "-",COUNTIF(독서목록!$D$2:$D$1091, B14)=0, , COUNTIF(독서목록!$D$2:$D$1091, B14)>0, COUNTIF(독서목록!$D$2:$D$1091, B14)) -> #NAME? | G14: 2026.02.02
B15: 넥서스 | C15: 유발 하라리 | D15: 김영사 | E15: =_xludf.IFS(COUNTIF(보류목록!$B$3:$B$1000, B15)>0, "-",COUNTIF(독서목록!$C$2:$C$1091, B15)=0, , COUNTIF(독서목록!$C$2:$C$1091, B15)>0, COUNTIF(독서목록!$C$2:$C$1091, B15)) -> #NAME? | F15: =_xludf.IFS(COUNTIF(보류목록!$C$3:$C$1000, B15)>0, "-",COUNTIF(독서목록!$D$2:$D$1091, B15)=0, , COUNTIF(독서목록!$D$2:$D$1091, B15)>0, COUNTIF(독서목록!$D$2:$D$1091, B15)) -> #NAME? | G15: 2026.01.05
... B25: 빌 캠벨, 실리콘밸리의 위대한 코치 | C25: 에릭 슈미트,조너선 로젠버그,앨런 이글 | D25: 김영사 | E25: =_xludf.IFS(COUNTIF(보류목록!$B$3:$B$1000, B25)>0, "-",COUNTIF(독서목록!$C$2:$C$1091, B25)=0, , COUNTIF(독서목록!$C$2:$C$1091, B25)>0, COUNTIF(독서목록!$C$2:$C$1091, B25)) -> #NAME? | F25: =_xludf.IFS(COUNTIF(보류목록!$C$3:$C$1000, B25)>0, "-",COUNTIF(독서목록!$D$2:$D$1091, B25)=0, , COUNTIF(독서목록!$D$2:$D$1091, B25)>0, COUNTIF(독서목록!$D$2:$D$1091, B25)) -> #NAME? | G25: 2025.10.10
B26: 100세 할머니 약국 | C26: 히루마 에이코 | D26: 월마 | E26: =_xludf.IFS(COUNTIF(보류목록!$B$3:$B$1000, B26)>0, "-",COUNTIF(독서목록!$C$2:$C$1091, B26)=0, , COUNTIF(독서목록!$C$2:$C$1091, B26)>0, COUNTIF(독서목록!$C$2:$C$1091, B26)) -> #NAME? | F26: =_xludf.IFS(COUNTIF(보류목록!$C$3:$C$1000, B26)>0, "-",COUNTIF(독서목록!$D$2:$D$1091, B26)=0, , COUNTIF(독서목록!$D$2:$D$1091, B26)>0, COUNTIF(독서목록!$D$2:$D$1091, B26)) -> #NAME? | G26: 2025.09.03 | H26: 기부 | I26: 25.12
B27: 우리가 빛의 속도로 갈 수 없다면 | C27: 김초엽 | D27: 허블 | E27: =_xludf.IFS(COUNTIF(보류목록!$B$3:$B$1000, B27)>0, "-",COUNTIF(독서목록!$C$2:$C$1091, B27)=0, , COUNTIF(독서목록!$C$2:$C$1091, B27)>0, COUNTIF(독서목록!$C$2:$C$1091, B27)) -> #NAME? | F27: =_xludf.IFS(COUNTIF(보류목록!$C$3:$C$1000, B27)>0, "-",COUNTIF(독서목록!$D$2:$D$1091, B27)=0, , COUNTIF(독서목록!$D$2:$D$1091, B27)>0, COUNTIF(독서목록!$D$2:$D$1091, B27)) -> #NAME? | G27: 2025.09.03 | H27: 기부 | I27: 25.12
B28: 팩트풀니스 | C28: 한스 로슬링 | D28: 김영사 | E28: =_xludf.IFS(COUNTIF(보류목록!$B$3:$B$1000, B28)>0, "-",COUNTIF(독서목록!$C$2:$C$1091, B28)=0, , COUNTIF(독서목록!$C$2:$C$1091, B28)>0, COUNTIF(독서목록!$C$2:$C$1091, B28)) -> #NAME? | F28: =_xludf.IFS(COUNTIF(보류목록!$C$3:$C$1000, B28)>0, "-",COUNTIF(독서목록!$D$2:$D$1091, B28)=0, , COUNTIF(독서목록!$D$2:$D$1091, B28)>0, COUNTIF(독서목록!$D$2:$D$1091, B28)) -> #NAME? | G28: 2025.09.03
B29: 투명사회 | C29: 한병철 | D29: 문학과지성사 | E29: =_xludf.IFS(COUNTIF(보류목록!$B$3:$B$1000, B29)>0, "-",COUNTIF(독서목록!$C$2:$C$1091, B29)=0, , COUNTIF(독서목록!$C$2:$C$1091, B29)>0, COUNTIF(독서목록!$C$2:$C$1091, B29)) -> #NAME? | F29: =_xludf.IFS(COUNTIF(보류목록!$C$3:$C$1000, B29)>0, "-",COUNTIF(독서목록!$D$2:$D$1091, B29)=0, , COUNTIF(독서목록!$D$2:$D$1091, B29)>0, COUNTIF(독서목록!$D$2:$D$1091, B29)) -> #NAME? | G29: 2025.08.07
B30: 우리는 어떻게 마음을 움직이는가 | C30: 크리스 보스,탈 라즈 | D30: 프롬북스 | E30: =_xludf.IFS(COUNTIF(보류목록!$B$3:$B$1000, B30)>0, "-",COUNTIF(독서목록!$C$2:$C$1091, B30)=0, , COUNTIF(독서목록!$C$2:$C$1091, B30)>0, COUNTIF(독서목록!$C$2:$C$1091, B30)) -> #NAME? | F30: =_xludf.IFS(COUNTIF(보류목록!$C$3:$C$1000, B30)>0, "-",COUNTIF(독서목록!$D$2:$D$1091, B30)=0, , COUNTIF(독서목록!$D$2:$D$1091, B30)>0, COUNTIF(독서목록!$D$2:$D$1091, B30)) -> #NAME? | G30: 2025.08.07
B31: 그거 사전 | C31: 홍성윤 | D31: 인플루엔셜 | E31: =_xludf.IFS(COUNTIF(보류목록!$B$3:$B$1000, B31)>0, "-",COUNTIF(독서목록!$C$2:$C$1091, B31)=0, , COUNTIF(독서목록!$C$2:$C$1091, B31)>0, COUNTIF(독서목록!$C$2:$C$1091, B31)) -> #NAME? | F31: =_xludf.IFS(COUNTIF(보류목록!$C$3:$C$1000, B31)>0, "-",COUNTIF(독서목록!$D$2:$D$1091, B31)=0, , COUNTIF(독서목록!$D$2:$D$1091, B31)>0, COUNTIF(독서목록!$D$2:$D$1091, B31)) -> #NAME? | G31: 2025.07.07
B32: 싱크 어게인 | C32: 애덤 그랜트 | D32: 한국경제신문 | E32: =_xludf.IFS(COUNTIF(보류목록!$B$3:$B$1000, B32)>0, "-",COUNTIF(독서목록!$C$2:$C$1091, B32)=0, , COUNTIF(독서목록!$C$2:$C$1091, B32)>0, COUNTIF(독서목록!$C$2:$C$1091, B32)) -> #NAME? | F32: =_xludf.IFS(COUNTIF(보류목록!$C$3:$C$1000, B32)>0, "-",COUNTIF(독서목록!$D$2:$D$1091, B32)=0, , COUNTIF(독서목록!$D$2:$D$1091, B32)>0, COUNTIF(독서목록!$D$2:$D$1091, B32)) -> #NAME? | G32: 2025.07.07
B33: 일의 감각 | C33: 조수용 | D33: B Media Company | E33: =_xludf.IFS(COUNTIF(보류목록!$B$3:$B$1000, B33)>0, "-",COUNTIF(독서목록!$C$2:$C$1091, B33)=0, , COUNTIF(독서목록!$C$2:$C$1091, B33)>0, COUNTIF(독서목록!$C$2:$C$1091, B33)) -> #NAME? | F33: =_xludf.IFS(COUNTIF(보류목록!$C$3:$C$1000, B33)>0, "-",COUNTIF(독서목록!$D$2:$D$1091, B33)=0, , COUNTIF(독서목록!$D$2:$D$1091, B33)>0, COUNTIF(독서목록!$D$2:$D$1091, B33)) -> #NAME? | G33: 2025.07.07
B34: 맡겨진 소녀 | C34: 클레어 키건 | D34: 다산책방 | E34: =_xludf.IFS(COUNTIF(보류목록!$B$3:$B$1000, B34)>0, "-",COUNTIF(독서목록!$C$2:$C$1091, B34)=0, , COUNTIF(독서목록!$C$2:$C$1091, B34)>0, COUNTIF(독서목록!$C$2:$C$1091, B34)) -> #NAME? | F34: =_xludf.IFS(COUNTIF(보류목록!$C$3:$C$1000, B34)>0, "-",COUNTIF(독서목록!$D$2:$D$1091, B34)=0, , COUNTIF(독서목록!$D$2:$D$1091, B34)>0, COUNTIF(독서목록!$D$2:$D$1091, B34)) -> #NAME? | G34: 2025.05.08
B35: 예술 도둑 | C35: 마이클 핀클 | D35: 생각의힘 | E35: =_xludf.IFS(COUNTIF(보류목록!$B$3:$B$1000, B35)>0, "-",COUNTIF(독서목록!$C$2:$C$1091, B35)=0, , COUNTIF(독서목록!$C$2:$C$1091, B35)>0, COUNTIF(독서목록!$C$2:$C$1091, B35)) -> #NAME? | F35: =_xludf.IFS(COUNTIF(보류목록!$C$3:$C$1000, B35)>0, "-",COUNTIF(독서목록!$D$2:$D$1091, B35)=0, , COUNTIF(독서목록!$D$2:$D$1091, B35)>0, COUNTIF(독서목록!$D$2:$D$1091, B35)) -> #NAME? | G35: 2025.05.08
B36: 팀워크의 부활 | C36: 페트릭 렌시오니 | D36: 위즈덤하우스 | E36: =_xludf.IFS(COUNTIF(보류목록!$B$3:$B$1000, B36)>0, "-",COUNTIF(독서목록!$C$2:$C$1091, B36)=0, , COUNTIF(독서목록!$C$2:$C$1091, B36)>0, COUNTIF(독서목록!$C$2:$C$1091, B36)) -> #NAME? | F36: =_xludf.IFS(COUNTIF(보류목록!$C$3:$C$1000, B36)>0, "-",COUNTIF(독서목록!$D$2:$D$1091, B36)=0, , COUNTIF(독서목록!$D$2:$D$1091, B36)>0, COUNTIF(독서목록!$D$2:$D$1091, B36)) -> #NAME? | G36: 2025.05.08
B37: 단어가 품은 세계 | C37: 황선엽 | D37: 빛의서가 | E37: =_xludf.IFS(COUNTIF(보류목록!$B$3:$B$1000, B37)>0, "-",COUNTIF(독서목록!$C$2:$C$1091, B37)=0, , COUNTIF(독서목록!$C$2:$C$1091, B37)>0, COUNTIF(독서목록!$C$2:$C$1091, B37)) -> #NAME? | F37: =_xludf.IFS(COUNTIF(보류목록!$C$3:$C$1000, B37)>0, "-",COUNTIF(독서목록!$D$2:$D$1091, B37)=0, , COUNTIF(독서목록!$D$2:$D$1091, B37)>0, COUNTIF(독서목록!$D$2:$D$1091, B37)) -> #NAME? | G37: 2025.03.07 | H37: 기부 | I37: 25.12
B38: 데미안(오리지널 초판본 디자인) | C38: 헤르만 헤세 | D38: 코너스톤 | E38: =_xludf.IFS(COUNTIF(보류목록!$B$3:$B$1000, B38)>0, "-",COUNTIF(독서목록!$C$2:$C$1091, B38)=0, , COUNTIF(독서목록!$C$2:$C$1091, B38)>0, COUNTIF(독서목록!$C$2:$C$1091, B38)) -> #NAME? | F38: =_xludf.IFS(COUNTIF(보류목록!$C$3:$C$1000, B38)>0, "-",COUNTIF(독서목록!$D$2:$D$1091, B38)=0, , COUNTIF(독서목록!$D$2:$D$1091, B38)>0, COUNTIF(독서목록!$D$2:$D$1091, B38)) -> #NAME? | G38: 2025.03.07
B39: 무기력이 무기력해지도록 | C39: 한창수 | D39: 알에이치코리아 | E39: =_xludf.IFS(COUNTIF(보류목록!$B$3:$B$1000, B39)>0, "-",COUNTIF(독서목록!$C$2:$C$1091, B39)=0, , COUNTIF(독서목록!$C$2:$C$1091, B39)>0, COUNTIF(독서목록!$C$2:$C$1091, B39)) -> #NAME? | F39: =_xludf.IFS(COUNTIF(보류목록!$C$3:$C$1000, B39)>0, "-",COUNTIF(독서목록!$D$2:$D$1091, B39)=0, , COUNTIF(독서목록!$D$2:$D$1091, B39)>0, COUNTIF(독서목록!$D$2:$D$1091, B39)) -> #NAME? | G39: 2025.03.07
B40: 불안 - 개정판 | C40: 알랭드 보통 | D40: 은행나무 | E40: =_xludf.IFS(COUNTIF(보류목록!$B$3:$B$1000, B40)>0, "-",COUNTIF(독서목록!$C$2:$C$1091, B40)=0, , COUNTIF(독서목록!$C$2:$C$1091, B40)>0, COUNTIF(독서목록!$C$2:$C$1091, B40)) -> #NAME? | F40: =_xludf.IFS(COUNTIF(보류목록!$C$3:$C$1000, B40)>0, "-",COUNTIF(독서목록!$D$2:$D$1091, B40)=0, , COUNTIF(독서목록!$D$2:$D$1091, B40)>0, COUNTIF(독서목록!$D$2:$D$1091, B40)) -> #NAME? | G40: 2025.03.07
B41: 초역 부처의 말 | C41: 코이케 류노스케 | D41: 포레스트북스 | E41: =_xludf.IFS(COUNTIF(보류목록!$B$3:$B$1000, B41)>0, "-",COUNTIF(독서목록!$C$2:$C$1091, B41)=0, , COUNTIF(독서목록!$C$2:$C$1091, B41)>0, COUNTIF(독서목록!$C$2:$C$1091, B41)) -> #NAME? | F41: =_xludf.IFS(COUNTIF(보류목록!$C$3:$C$1000, B41)>0, "-",COUNTIF(독서목록!$D$2:$D$1091, B41)=0, , COUNTIF(독서목록!$D$2:$D$1091, B41)>0, COUNTIF(독서목록!$D$2:$D$1091, B41)) -> #NAME? | G41: 2025.02.06
B42: THICK data | C42: 백영재 | D42: 테라코타 | E42: =_xludf.IFS(COUNTIF(보류목록!$B$3:$B$1000, B42)>0, "-",COUNTIF(독서목록!$C$2:$C$1091, B42)=0, , COUNTIF(독서목록!$C$2:$C$1091, B42)>0, COUNTIF(독서목록!$C$2:$C$1091, B42)) -> #NAME? | F42: =_xludf.IFS(COUNTIF(보류목록!$C$3:$C$1000, B42)>0, "-",COUNTIF(독서목록!$D$2:$D$1091, B42)=0, , COUNTIF(독서목록!$D$2:$D$1091, B42)>0, COUNTIF(독서목록!$D$2:$D$1091, B42)) -> #NAME? | G42: 2025.01.07
B43: 새들이 남쪽으로 가는 날 | C43: 리사 리드센 | D43: 북파머스 | E43: =_xludf.IFS(COUNTIF(보류목록!$B$3:$B$1000, B43)>0, "-",COUNTIF(독서목록!$C$2:$C$1091, B43)=0, , COUNTIF(독서목록!$C$2:$C$1091, B43)>0, COUNTIF(독서목록!$C$2:$C$1091, B43)) -> #NAME? | F43: =_xludf.IFS(COUNTIF(보류목록!$C$3:$C$1000, B43)>0, "-",COUNTIF(독서목록!$D$2:$D$1091, B43)=0, , COUNTIF(독서목록!$D$2:$D$1091, B43)>0, COUNTIF(독서목록!$D$2:$D$1091, B43)) -> #NAME? | G43: 2025.01.07
B44: 희랍어 시간 | C44: 한강 | D44: 문학동네 | E44: =_xludf.IFS(COUNTIF(보류목록!$B$3:$B$1000, B44)>0, "-",COUNTIF(독서목록!$C$2:$C$1091, B44)=0, , COUNTIF(독서목록!$C$2:$C$1091, B44)>0, COUNTIF(독서목록!$C$2:$C$1091, B44)) -> #NAME? | F44: =_xludf.IFS(COUNTIF(보류목록!$C$3:$C$1000, B44)>0, "-",COUNTIF(독서목록!$D$2:$D$1091, B44)=0, , COUNTIF(독서목록!$D$2:$D$1091, B44)>0, COUNTIF(독서목록!$D$2:$D$1091, B44)) -> #NAME? | G44: 2024.12.02
B45: 마음의 기술 | C45: 안 엘렌 클레르, 뱅상 트리부 | D45: 상상스퀘어 | E45: =_xludf.IFS(COUNTIF(보류목록!$B$3:$B$1000, B45)>0, "-",COUNTIF(독서목록!$C$2:$C$1091, B45)=0, , COUNTIF(독서목록!$C$2:$C$1091, B45)>0, COUNTIF(독서목록!$C$2:$C$1091, B45)) -> #NAME? | F45: =_xludf.IFS(COUNTIF(보류목록!$C$3:$C$1000, B45)>0, "-",COUNTIF(독서목록!$D$2:$D$1091, B45)=0, , COUNTIF(독서목록!$D$2:$D$1091, B45)>0, COUNTIF(독서목록!$D$2:$D$1091, B45)) -> #NAME? | G45: 2024.12.02
B46: 소년이 온다 | C46: 한강 | D46: 창비 | E46: =_xludf.IFS(COUNTIF(보류목록!$B$3:$B$1000, B46)>0, "-",COUNTIF(독서목록!$C$2:$C$1091, B46)=0, , COUNTIF(독서목록!$C$2:$C$1091, B46)>0, COUNTIF(독서목록!$C$2:$C$1091, B46)) -> #NAME? | F46: =_xludf.IFS(COUNTIF(보류목록!$C$3:$C$1000, B46)>0, "-",COUNTIF(독서목록!$D$2:$D$1091, B46)=0, , COUNTIF(독서목록!$D$2:$D$1091, B46)>0, COUNTIF(독서목록!$D$2:$D$1091, B46)) -> #NAME? | G46: 2024.11.06
B47: 작별하지 않는다 | C47: 한강 | D47: 문학동네 | E47: =_xludf.IFS(COUNTIF(보류목록!$B$3:$B$1000, B47)>0, "-",COUNTIF(독서목록!$C$2:$C$1091, B47)=0, , COUNTIF(독서목록!$C$2:$C$1091, B47)>0, COUNTIF(독서목록!$C$2:$C$1091, B47)) -> #NAME? | F47: =_xludf.IFS(COUNTIF(보류목록!$C$3:$C$1000, B47)>0, "-",COUNTIF(독서목록!$D$2:$D$1091, B47)=0, , COUNTIF(독서목록!$D$2:$D$1091, B47)>0, COUNTIF(독서목록!$D$2:$D$1091, B47)) -> #NAME? | G47: 2024.11.06
B48: 채식주의자 | C48: 한강 | D48: 창비 | E48: =_xludf.IFS(COUNTIF(보류목록!$B$3:$B$1000, B48)>0, "-",COUNTIF(독서목록!$C$2:$C$1091, B48)=0, , COUNTIF(독서목록!$C$2:$C$1091, B48)>0, COUNTIF(독서목록!$C$2:$C$1091, B48)) -> #NAME? | F48: =_xludf.IFS(COUNTIF(보류목록!$C$3:$C$1000, B48)>0, "-",COUNTIF(독서목록!$D$2:$D$1091, B48)=0, , COUNTIF(독서목록!$D$2:$D$1091, B48)>0, COUNTIF(독서목록!$D$2:$D$1091, B48)) -> #NAME? | G48: 2024.11.06
B49: 흰 | C49: 한강 | D49: 문학동네 | E49: =_xludf.IFS(COUNTIF(보류목록!$B$3:$B$1000, B49)>0, "-",COUNTIF(독서목록!$C$2:$C$1091, B49)=0, , COUNTIF(독서목록!$C$2:$C$1091, B49)>0, COUNTIF(독서목록!$C$2:$C$1091, B49)) -> #NAME? | F49: =_xludf.IFS(COUNTIF(보류목록!$C$3:$C$1000, B49)>0, "-",COUNTIF(독서목록!$D$2:$D$1091, B49)=0, , COUNTIF(독서목록!$D$2:$D$1091, B49)>0, COUNTIF(독서목록!$D$2:$D$1091, B49)) -> #NAME? | G49: 2024.11.06
...

Sheet IT서적
C1: IT BOOKS
B2: 책 이름 | C2: 작가 | D2: 출판사 | E2: 대현 | F2: 문선 | G2: 구입 날짜
B4: 요즘 당근 AI 개발 | C4: 당근팀 | D4: 골든래빗 | G4: 2025.11.03
B5: MCP로 똑똑하게 일하는 법 | C5: 케이트리 | D5: 제이펍 | G5: 2025.08.07
B6: 개발자를 넘어 기술 리더로 가는 길 | C6: 타냐 라일리 | D6: 디코딩 | G6: 2025.04.08
B7: 데이터 메시 | C7: 세막 데그하니 | D7: 한빛미디어 | G7: 2025.04.08
B8: 모던 리액트 Deep Dive | C8: 김용찬 | D8: 위키북스 | E8: O | G8: 2025.02.06
B9: 생활코딩! Ract 리액트 프로그래밍 | C9: 이고잉 | D9: 위키북스 | E9: O | G9: 2025.01.07
B10: 소프트웨어 설계의 정석 | C10: 요시하라 쇼자부로 | D10: 한빛미디어 | G10: 2024.12.02
B11: 개발자 원칙 | C11: 박성철 외 8명 | D11: 골든래빗 | F11: O | G11: 2024.10.11
B12: 코드 밖 커뮤니케이션 | C12: 재퀴 리드 | D12: 한빛미디어 | F12: O | G12: 2024.10.11
B13: Do it! Vue.js 입문 | C13: 장기효 | D13: 이지스퍼블리싱 | E13: O | G13: 2024.07.04
B14: 데이터아키텍처 준전문가(DAsP) 한 권으로 끝내기 | C14: 김상목 | D14: 마크리더 | G14: 2024.07.04
B15: SQL 자격검정 실전문제 | C15: 한국데이터산업진흥원 | D15: 한국데이터산업진흥원 | G15: 2024.05.11
B16: 피닉스 프로젝트 | C16: 진킴, 케빈 베어, 조지 스패포트 | D16: 에이콘 | G16: 2023.08.22
B17: 데이터 모델링 실전처럼 시작하기 | C17: 박종원 | D17: 세나북스 | E17: O | F17: O | G17: 2023.05.20
B18: 데이터 분석 준전문가 | C18: 윤종식 | D18: 데이터에듀 | G18: 2023.03.10
B19: 데이터 모델링 이야기 | C19: 김상래 | D19: 한빛미디어 | E19: O | F19: O | G19: 2023.01.05
B20: IT 엔지니어를 위한 네트워크 입문 | C20: 고재성, 이상훈 | D20: 길벗 | F20: O | G20: 2022.12.09
B21: 사용자 스토리 | C21: 마이크 콘 | D21: 인사이트 | E21: O | F21: O | G21: 2022.09.05
B22: 익스트림 프로그래밍 | C22: 켄트 벡, 신시아 안드레스 | D22: 인사이트 | E22: O | F22: O | G22: 2022.08.05
B23: 애자일 회고 | C23: 에스더 더비, 다이애나 라센 | D23: 인사이트 | E23: O | F23: O | G23: 2022.08.05
B24: 클린 코더 | C24: 로버트 C.마틴 | D24: 인사이트 | E24: O | F24: O | G24: 2022.06.08
B25: 읽기 좋은 코드가 좋은 코드다 | C25: 더스트 보즈웨, 트레버 파우커 | D25: 한빛미디어 | E25: O | F25: O | G25: 2022.06.08
B26: 레거시 코드 활용 전략 | C26: 마이클 C. 페더스 | D26: 에이콘 | G26: 2022.05.11
B27: 함께 자라기 | C27: 김창준 | D27: 인사이트 | E27: O | F27: O | G27: 2022.05.11
B28: 도메인 주도 개발 시작하기 | C28: 최범균 | D28: 한빛미디어 | E28: O | G28: 2022.04.13
B29: 테스트 주도 개발 | C29: 켄트 벡 | D29: 인사이트 | E29: O | F29: O | G29: 2022.04.13
B30: 코드로 배우는 스프링 부트 웹 프로젝트 | C30: 구멍가게 코딩단 | D30: 남가람북스 | F30: O | G30: 2022.03.13
B31: 아파치 카프가 | C31: 최원영 | D31: 비제이퍼블릭 | G31: 2022.02.03
B32: 클린 코드 | C32: 로버트 C.마틴 | D32: 인사이트 | E32: O | F32: O | G32: 2022.06.08
B33: 클린 아키텍처 | C33: 로버트 C.마틴 | D33: 인사이트 | E33: O | F33: O
B34: 데이터 중심 애플리케이션 설계 | C34: 마틴 클레이프만 | D34: 위키북스 | G34: 2021.12.30
B35: 클린 애자일 | C35: 로버트 C.마틴 | D35: 인사이트 | E35: O | G35: 2021.12.30
B36: 스프링 부트와 AWS로 혼자 구현하는 웹 서비스 | C36: 이동욱 | D36: 프리렉 | G36: 2021.11.23
B37: 배워서 바로 쓰는 14가지 AWS 구축 패턴 | C37: 가와카미 아키히사 | D37: 한빛미디어 | E37: O | G37: 2021.11.23
B38: 클라우드 네이티브 인프라스트럭처 | C38: 저스틴 게리슨, 크리스 노바 | D38: 책만 | G38: 2021.10.29
B39: 마이크로서비스 도입 이렇게 한다 | C39: 샘 뉴먼 | D39: 책만 | E39: O | G39: 2021.10.29
B40: 도메인 주도 설계 철저 입문 | C40: 나루세 마사노부 | D40: 위키북스 | F40: O | G40: 2021.09.27
B41: 소프트웨어 아키텍처 : 이론과 실제 - 개정3판 | C41: 렌 베스 | D41: 에이콘출판 | E41: O | G41: 2021.07.29
...

Sheet 통계
B1: # 독서
B2: Year | C2: 대현 | D2: 문선 | E2: 합계
B3: 연도불명 | C3: =COUNTIFS(독서목록!$B$46:$B$1201, B3, 독서목록!$C$46:$C$1201, "*") -> 0 | D3: =COUNTIFS(독서목록!$B$46:$B$1201, B3, 독서목록!$D$46:$D$1201, "*") -> 80 | E3: =SUM(C3:D3) -> 80
B4: 2010 | C4: =COUNTIFS(독서목록!$B$46:$B$1201, B4, 독서목록!$C$46:$C$1201, "*") -> 41 | D4: =COUNTIFS(독서목록!$B$46:$B$1201, B4, 독서목록!$D$46:$D$1201, "*") -> 47 | E4: =SUM(C4:D4) -> 88
B5: =B4+1 -> 2011 | C5: =COUNTIFS(독서목록!$B$46:$B$1201, B5, 독서목록!$C$46:$C$1201, "*") -> 55 | D5: =COUNTIFS(독서목록!$B$46:$B$1201, B5, 독서목록!$D$46:$D$1201, "*") -> 49 | E5: =SUM(C5:D5) -> 104
B6: =B5+1 -> 2012 | C6: =COUNTIFS(독서목록!$B$46:$B$1201, B6, 독서목록!$C$46:$C$1201, "*") -> 53 | D6: =COUNTIFS(독서목록!$B$46:$B$1201, B6, 독서목록!$D$46:$D$1201, "*") -> 57 | E6: =SUM(C6:D6) -> 110
B7: =B6+1 -> 2013 | C7: =COUNTIFS(독서목록!$B$46:$B$1201, B7, 독서목록!$C$46:$C$1201, "*") -> 43 | D7: =COUNTIFS(독서목록!$B$46:$B$1201, B7, 독서목록!$D$46:$D$1201, "*") -> 34 | E7: =SUM(C7:D7) -> 77
B8: =B7+1 -> 2014 | C8: =COUNTIFS(독서목록!$B$46:$B$1201, B8, 독서목록!$C$46:$C$1201, "*") -> 33 | D8: =COUNTIFS(독서목록!$B$46:$B$1201, B8, 독서목록!$D$46:$D$1201, "*") -> 29 | E8: =SUM(C8:D8) -> 62
B9: =B8+1 -> 2015 | C9: =COUNTIFS(독서목록!$B$46:$B$1201, B9, 독서목록!$C$46:$C$1201, "*") -> 41 | D9: =COUNTIFS(독서목록!$B$46:$B$1201, B9, 독서목록!$D$46:$D$1201, "*") -> 30 | E9: =SUM(C9:D9) -> 71
B10: =B9+1 -> 2016 | C10: =COUNTIFS(독서목록!$B$46:$B$1201, B10, 독서목록!$C$46:$C$1201, "*") -> 30 | D10: =COUNTIFS(독서목록!$B$46:$B$1201, B10, 독서목록!$D$46:$D$1201, "*") -> 19 | E10: =SUM(C10:D10) -> 49
B11: =B10+1 -> 2017 | C11: =COUNTIFS(독서목록!$B$46:$B$1201, B11, 독서목록!$C$46:$C$1201, "*") -> 25 | D11: =COUNTIFS(독서목록!$B$46:$B$1201, B11, 독서목록!$D$46:$D$1201, "*") -> 24 | E11: =SUM(C11:D11) -> 49
B12: =B11+1 -> 2018 | C12: =COUNTIFS(독서목록!$B$46:$B$1201, B12, 독서목록!$C$46:$C$1201, "*") -> 43 | D12: =COUNTIFS(독서목록!$B$46:$B$1201, B12, 독서목록!$D$46:$D$1201, "*") -> 34 | E12: =SUM(C12:D12) -> 77
B13: =B12+1 -> 2019 | C13: =COUNTIFS(독서목록!$B$46:$B$1201, B13, 독서목록!$C$46:$C$1201, "*") -> 10 | D13: =COUNTIFS(독서목록!$B$46:$B$1201, B13, 독서목록!$D$46:$D$1201, "*") -> 4 | E13: =SUM(C13:D13) -> 14
B14: =B13+1 -> 2020 | C14: =COUNTIFS(독서목록!$B$46:$B$1201, B14, 독서목록!$C$46:$C$1201, "*") -> 11 | D14: =COUNTIFS(독서목록!$B$46:$B$1201, B14, 독서목록!$D$46:$D$1201, "*") -> 17 | E14: =SUM(C14:D14) -> 28
B15: =B14+1 -> 2021 | C15: =COUNTIFS(독서목록!$B$46:$B$1201, B15, 독서목록!$C$46:$C$1201, "*") -> 15 | D15: =COUNTIFS(독서목록!$B$46:$B$1201, B15, 독서목록!$D$46:$D$1201, "*") -> 14 | E15: =SUM(C15:D15) -> 29
B16: 2022 | C16: =COUNTIFS(독서목록!$B$46:$B$1201, B16, 독서목록!$C$46:$C$1201, "*") -> 17 | D16: =COUNTIFS(독서목록!$B$46:$B$1201, B16, 독서목록!$D$46:$D$1201, "*") -> 10 | E16: =SUM(C16:D16) -> 27
B17: 2023 | C17: =COUNTIFS(독서목록!$B$46:$B$1201, B17, 독서목록!$C$46:$C$1201, "*") -> 32 | D17: =COUNTIFS(독서목록!$B$46:$B$1201, B17, 독서목록!$D$46:$D$1201, "*") -> 26 | E17: =SUM(C17:D17) -> 58
B18: 2024 | C18: =COUNTIFS(독서목록!$B$46:$B$1201, B18, 독서목록!$C$46:$C$1201, "*") -> 30 | D18: =COUNTIFS(독서목록!$B$46:$B$1201, B18, 독서목록!$D$46:$D$1201, "*") -> 31 | E18: =SUM(C18:D18) -> 61
B19: 2025 | C19: =COUNTIFS(독서목록!$B$3:$B$1201, B19, 독서목록!$C$3:$C$1201, "*") -> 26 | D19: =COUNTIFS(독서목록!$B$3:$B$1201, B19, 독서목록!$D$3:$D$1201, "*") -> 20 | E19: =SUM(C19:D19) -> 46
B20: 2026 | C20: =COUNTIFS(독서목록!$B$3:$B$1201, B20, 독서목록!$C$3:$C$1201, "*") -> 8 | D20: =COUNTIFS(독서목록!$B$3:$B$1201, B20, 독서목록!$D$3:$D$1201, "*") -> 5 | E20: =SUM(C20:D20) -> 13
B22: Average | C22: =ROUND(SUM(C3:C19)/COUNT(C3:C19), 1) -> 29.7 | D22: =ROUND(SUM(D3:D19)/COUNT(D3:D19), 1) -> 30.9 | E22: =ROUND(SUM(E3:E19)/COUNT(E3:E19), 1) -> 60.6
B23: Total | C23: =SUM(C3:C19) -> 505 | D23: =SUM(D3:D19) -> 525 | E23: =SUM(C23,D23) -> 1030
C25: 대현 | D25: 문선 | E25: 공통
B26: 읽음 | C26: =COUNTIF(도서목록!$E$3:$E$1103, ">=1") -> 0 | D26: =COUNTIF(도서목록!$F$3:$F$1103, ">=1") -> 2 | E26: =COUNTIFS(도서목록!$E$3:$E$1103, ">=1", 도서목록!$F$3:$F$1103, ">=1")+COUNTIFS(도서목록!$E$3:$E$1103, ">=1", 도서목록!$F$3:$F$1103, "O") -> 0
B27: 안 읽을 | C27: =COUNTIF(도서목록!$E$3:$E$1103, "-") -> 1 | D27: =COUNTIF(도서목록!$F$3:$F$1103, "-") -> 1 | E27: =COUNTIFS(도서목록!$E$3:$E$1103, "-", 도서목록!$F$3:$F$1103, "-") -> 1
B28: 읽어야 할 | C28: =C30-C26-C27 -> 558 | D28: =C30-D26-D27 -> 556 | E28: =COUNTIFS(도서목록!$E$3:$E$1103, "", 도서목록!$F$3:$F$1103, "") -> 530
B30: 구입 | C30: =도서목록!B1 -> 559
B31: 기부 | C31: =COUNTIF(도서목록!H3:H573, "기부") -> 152
B32: 판매 | C32: =COUNTIF(도서목록!H3:H573, "판매") -> 157
B33: 보관 | C33: =C30-C31-C32 -> 250

Sheet 독서목록
B2: 년 | C2: 대현 | D2: 문선
B4: 2026 | C4: YES를 이끌어내는 협상법 | D4: 흐르는 강물처럼-셀리 리드
B5: 2026 | C5: 물고기는 존재하지 않는다 | D5: 천천히 다정하게
B6: 2026 | C6: 위버멘쉬 | D6: 하얼빈
B7: 2026 | C7: 하얼빈 | D7: 그랜드 부다페스트 호텔
B8: 2026 | C8: 쓰는 사람 | D8: 쓰는 사람
B9: 2026 | C9: 빌 캠벨, 실리콘밸리의 위대한 코치
B10: 2026 | C10: YES를 이끌어내는 협상법
B11: 2026 | C11: 팩트풀니스
B12: 2026
B13: 2026
B14: 2026
B15: 2026
B16: 2026
B17: 2026
B18: 2026
B19: 2026
B20: 2025 | C20: 마음의 기술 | D20: 면도날
B21: 2025 | C21: 생활코딩! Ract 리액트 프로그래밍 | D21: 작별하지 않는다
B22: 2025 | C22: 새들이 남쪽으로 가는 날 | D22: 초역 부처의 말
B23: 2025 | C23: THICK data | D23: 무기력이 무기력해지도록
B24: 2025 | C24: 초역 부처의 말 | D24: 흰
B25: 2025 | C25: 데미안(오리지널 초판본 디자인) | D25: 개발자 원칙
B26: 2025 | C26: 모던 리액트 Deep Dive | D26: 불안 - 개정판
B27: 2025 | C27: 흰 | D27: 채식주의자
B28: 2025 | C28: 단어가 품은 세계 | D28: 단어가 품은 세계
B29: 2025 | C29: 무기력이 무기력해지도록 | D29: 팀워크의 부활
B30: 2025 | C30: 예술 도둑 | D30: 맡겨진 소녀
B31: 2025 | C31: 맡겨진 소녀 | D31: 소년이 온다
... B39: 2025 | C39: 우리는 어떻게 마음을 움직이는가 | D39: 고도를 기다리며
B40: 2025 | C40: 천천히 다정하게
B41: 2025 | C41: 비 그친 오후의 헌책방
B42: 2025 | C42: 인간 실격
B43: 2025 | C43: 우리가 빛의 속도로 갈 수 없다면
B44: 2025 | C44: 흐르는 강물처럼-셀리 리드
B45: 2025 | C45: 아버지의 해방일지
B46: 2024 | C46: 마흔에 읽는 쇼펜하우어 | D46: 도어
B47: 2024 | C47: 더 좋은 삶을 위한 철학 | D47: 마흔에 읽는 쇼펜하우어
B48: 2024 | C48: IT 천재들 | D48: 인간 실격
B49: 2024 | C49: 칼 로저스의 사람-중심 상담 | D49: 이처럼 사소한 것들
...

Sheet 보류목록
B2: 대현 | C2: 문선
B3: 시지프 신화 | C3: 시지프 신화
B4: 빈센트 반고흐 | C4: 설득의 심리학2
B5: 소울메이트 | C5: 몽유병자들(하)
B6: 향수 | C6: 몽유병자들(상)
B7: 긍정의 한줄 | C7: 백범일지
B8: 화성에서 온 남자 금성에서 온 여자 | C8: 월드오브워크래프트 스톰레인지
B9: 샐러드 & 소스 만들기 | C9: 스피드 당구
B10: 스피드 당구 | C10: 제이나 프라우드무어 : 전쟁의 물결
B11: 밥 먹는 술집을 차렸습니다 | C11: 월드오브워크래프트 볼진: 호드의 그림자
B12: 적의 화장법 | C12: 꼬마 니콜라 - 나 홀로 기차 여행
B13: 프랑스 여자는 늙지 않는다 | C13: 꼬마 니콜라 - 공동 꼴찌
... B35: 해리포터와 죽음의 성물 - 1 | C35: 현대 물리학과 동양 사상
B36: 해리포터와 혼혈왕자 - 4
B37: 해리포터와 혼혈왕자 - 3
B38: 해리포터와 혼혈왕자 - 2
B39: 해리포터와 혼혈왕자 - 1
B40: 해리포터와 불사조 기사단 - 5
B41: 해리포터와 불사조 기사단 - 4
B42: 해리포터와 불사조 기사단 - 3
B43: 해리포터와 불사조 기사단 - 2
B44: 해리포터와 불사조 기사단 - 1
B45: 해리포터와 불의 잔 - 4
B46: 해리포터와 불의 잔 - 3
B47: 해리포터와 불의 잔 - 2
... B60: 과자, 내 아이를 해치는 달콤한 유혹
